<mujoco model="ur5">
    <include file="scene.xml"/>

    <compiler angle="radian" meshdir="/home/ubuntu/code/test_mujoco/xml/ur5/ur5/collision" />
    <size njmax="500" nconmax="100" />
    <asset>
        <mesh name="base" file="base.stl" />
        <mesh name="shoulder" file="shoulder.stl" />
        <mesh name="upperarm" file="upperarm.stl" />
        <mesh name="forearm" file="forearm.stl" />
        <mesh name="wrist1" file="wrist1.stl" />
        <mesh name="wrist2" file="wrist2.stl" />
        <mesh name="wrist3" file="wrist3.stl" />
    </asset>
    <worldbody>
        <geom type="mesh" contype="0" conaffinity="0" group="0" rgba="0.7 0.7 0.7 1" mesh="base" />
        <!-- <geom type="mesh" rgba="0.7 0.7 0.7 1" mesh="base" /> -->

        <!-- <body pos="0 0 1.5" euler="0 1.57 0">
            <joint type="free"/>
            <inertial pos="0 0 0" mass="1" diaginertia="0.01 0.01 0.01"/>
            <geom type="box" size=".1 .2 .3" rgba="0 0 .9 1"/>
        </body> -->

        <body name="shoulder_link" pos="0 0 0.089159">
            <inertial pos="0 0 0" mass="3.7" diaginertia="0.0102675 0.0102675 0.00666" />
            <joint name="shoulder_pan_joint" pos="0 0 0" axis="0 0 1" limited="true" range="-6.28319 6.28319" />
            <geom type="mesh" contype="0" conaffinity="0" group="1" rgba="0.7 0.7 0.7 1" mesh="shoulder" />
            <geom type="mesh" rgba="0.7 0.7 0.7 1" mesh="shoulder" />

            <body name="upper_arm_link" pos="0 0.13585 0" quat="1 0 0 0">
                <inertial pos="0 0 0.28" mass="8.393" diaginertia="0.226891 0.226891 0.0151074" />
                <joint name="shoulder_lift_joint" pos="0 0 0" axis="0 1 0" limited="true" range="-6.28319 6.28319" />
                <geom type="mesh" contype="0" conaffinity="0" group="1" rgba="0.7 0.7 0.7 1" mesh="upperarm" />
                <geom type="mesh" rgba="0.7 0.7 0.7 1" mesh="upperarm" />
            </body>

        </body>
    </worldbody>
</mujoco>
