<mujoco>
    <compiler angle="radian" />
    <worldbody>
        <light diffuse=".5 .5 .5" pos="0 0 3" dir="0 0 -1"/>
        <geom type="plane" size="10 10 0.1" rgba=".9 0 0 1"/>
        <body pos="0 0 .25" >
            <inertial pos="0 0 0" mass="10" diaginertia="0.0102675 0.0102675 0.00666" />
            <joint type="slide" axis="0 0 1" />
            <geom type="box" contype="0" conaffinity="0" group="1" size=".1 .1 .25" rgba="0 .9 0 1"/>
            <geom type='box' size=".1 .1 .25" rgba="0 .9 0 1"/>
            <body pos="0 0 .5" quat="1 0 0 0">
                <inertial pos="0 0 0" mass="0" diaginertia="0.0102675 0.0102675 0.00666" />
                <joint name="joint1" type="hinge" pos="0 0 -0.3" axis="0 1 0" limited="true" range="-3.14159 3.14159" />
                <geom type="box" contype="0" conaffinity="0" group="1" size=".1 .1 .2" rgba="0 .9 0 1"/>
                <geom type="box" size=".1 .1 .2" rgba="1 .9 0 1"/>
            </body>
        </body>        
    </worldbody>
    <actuator>
        <motor name='joint1' ctrllimited="true" ctrlrange="-0.5 0.5" joint='joint1' gear="101"/> <!--range -150 150-->
    </actuator>
</mujoco>